<?xml version="1.0"?>
<robot name="foosball_table">
  <link name="table">
    <visual>
      <origin xyz="0.0 0.0 0.0"/>
      <geometry>
        <mesh filename="meshes/table.obj" scale="0.001 0.001 0.001"/>
      </geometry>
    </visual>
    <collision>
      <origin xyz="0.0 0.0 0.0"/>
      <geometry>
        <mesh filename="meshes/table.obj" scale="0.001 0.001 0.001"/>
      </geometry>
    </collision>
  </link>


  <link name="empty_goalie_team_1"/>
  <link name="goalie_team_1">
    <visual>
      <origin xyz="0.0 0.0 0.0"/>
      <geometry>
        <mesh filename="meshes/1-bar-centered.obj" scale="1 1 1"/>
      </geometry>
    </visual>
    <collision>
      <origin xyz="0.0 0.0 0.0"/>
      <geometry>
        <mesh filename="meshes/1-bar-centered.obj" scale="1 1 1"/>
      </geometry>
    </collision>
    <inertial>
      <mass value="0.7638"/>
      <inertia ixx="0.099" ixy="-0.000001283" ixz="0.000000003289" iyy="0.0" iyz="0.00004499" izz="0.099"/>
    </inertial>
  </link>

  <link name="empty_2_bar_team_1"/>
  <link name="2_bar_team_1">
    <visual>
      <origin xyz="0.0 0.0 0.0"/>
      <geometry>
        <mesh filename="meshes/2-bar-centered.obj" scale="1 1 1"/>
      </geometry>
    </visual>
    <collision>
      <origin xyz="0.0 0.0 0.0"/>
      <geometry>
        <mesh filename="meshes/2-bar-centered.obj" scale="1 1 1"/>
      </geometry>
    </collision>
    <inertial>
      <mass value="0.7638"/>
      <inertia ixx="0.099" ixy="-0.000001283" ixz="0.000000003289" iyy="0.0" iyz="0.00004499" izz="0.099"/>
    </inertial>
  </link>

  <link name="empty_5_bar_team_1"/>
  <link name="5_bar_team_1">
    <visual>
      <origin xyz="0.0 0.0 0.0"/>
      <geometry>
        <mesh filename="meshes/5-bar-centered.obj" scale="1 1 1"/>
      </geometry>
    </visual>
    <collision>
      <origin xyz="0.0 0.0 0.0"/>
      <geometry>
        <mesh filename="meshes/5-bar-centered.obj" scale="1 1 1"/>
      </geometry>
    </collision>
    <inertial>
      <mass value="0.7638"/>
      <inertia ixx="0.099" ixy="-0.000001283" ixz="0.000000003289" iyy="0.0" iyz="0.00004499" izz="0.099"/>
    </inertial>
  </link>

  <link name="empty_3_bar_team_1"/>
  <link name="3_bar_team_1">
    <visual>
      <origin xyz="0.0 0.0 0.0"/>
      <geometry>
        <mesh filename="meshes/3-bar-centered.obj" scale="1 1 1"/>
      </geometry>
    </visual>
    <collision>
      <origin xyz="0.0 0.0 0.0"/>
      <geometry>
        <mesh filename="meshes/3-bar-centered.obj" scale="1 1 1"/>
      </geometry>
    </collision>
    <inertial>
      <mass value="0.7638"/>
      <inertia ixx="0.099" ixy="-0.000001283" ixz="0.000000003289" iyy="0.0" iyz="0.00004499" izz="0.099"/>
    </inertial>
  </link>




  <link name="empty_goalie_team_2"/>
  <link name="goalie_team_2">
    <visual>
      <origin xyz="0.0 0.0 0.0"/>
      <geometry>
        <mesh filename="meshes/1-bar-centered.obj" scale="1 1 1"/>
      </geometry>
    </visual>
    <collision>
      <origin xyz="0.0 0.0 0.0"/>
      <geometry>
        <mesh filename="meshes/1-bar-centered.obj" scale="1 1 1"/>
      </geometry>
    </collision>
    <inertial>
      <mass value="0.7638"/>
      <inertia ixx="0.099" ixy="-0.000001283" ixz="0.000000003289" iyy="0.0" iyz="0.00004499" izz="0.099"/>
    </inertial>
  </link>

  <link name="empty_2_bar_team_2"/>
  <link name="2_bar_team_2">
    <visual>
      <origin xyz="0.0 0.0 0.0"/>
      <geometry>
        <mesh filename="meshes/2-bar-centered.obj" scale="1 1 1"/>
      </geometry>
    </visual>
    <collision>
      <origin xyz="0.0 0.0 0.0"/>
      <geometry>
        <mesh filename="meshes/2-bar-centered.obj" scale="1 1 1"/>
      </geometry>
    </collision>
    <inertial>
      <mass value="0.7638"/>
      <inertia ixx="0.099" ixy="-0.000001283" ixz="0.000000003289" iyy="0.0" iyz="0.00004499" izz="0.099"/>
    </inertial>
  </link>

  <link name="empty_5_bar_team_2"/>
  <link name="5_bar_team_2">
    <visual>
      <origin xyz="0.0 0.0 0.0"/>
      <geometry>
        <mesh filename="meshes/5-bar-centered.obj" scale="1 1 1"/>
      </geometry>
    </visual>
    <collision>
      <origin xyz="0.0 0.0 0.0"/>
      <geometry>
        <mesh filename="meshes/5-bar-centered.obj" scale="1 1 1"/>
      </geometry>
    </collision>
    <inertial>
      <mass value="0.7638"/>
      <inertia ixx="0.099" ixy="-0.000001283" ixz="0.000000003289" iyy="0.0" iyz="0.00004499" izz="0.099"/>
    </inertial>
  </link>

  <link name="empty_3_bar_team_2"/>
  <link name="3_bar_team_2">
    <visual>
      <origin xyz="0.0 0.0 0.0"/>
      <geometry>
        <mesh filename="meshes/3-bar-centered.obj" scale="1 1 1"/>
      </geometry>
    </visual>
    <collision>
      <origin xyz="0.0 0.0 0.0"/>
      <geometry>
        <mesh filename="meshes/3-bar-centered.obj" scale="1 1 1"/>
      </geometry>
    </collision>
    <inertial>
      <mass value="0.7638"/>
      <inertia ixx="0.099" ixy="-0.000001283" ixz="0.000000003289" iyy="0.0" iyz="0.00004499" izz="0.099"/>
    </inertial>
  </link>

<joint name="goalie_team_1_prismatic_joint" type="prismatic">
  <parent link="table"/>
  <child link="empty_goalie_team_1"/>
  <limit effort="9999" velocity="9999" lower="-0.147" upper="0.147"/>
  <axis xyz="0 1 0"/>
  <origin xyz="0.525 0.0 0.360054"/>
</joint>
<joint name="goalie_team_1_revolute_joint" type="revolute">
  <parent link="empty_goalie_team_1"/>
  <child link="goalie_team_1"/>
  <axis xyz="0 1 0"/>
</joint>

<joint name="2_bar_team_1_prismatic_joint" type="prismatic">
  <parent link="table"/>
  <child link="empty_2_bar_team_1"/>
  <limit effort="9999" velocity="9999" lower="-0.187" upper="0.187"/>
  <axis xyz="0 1 0"/>
  <origin xyz="0.375 0.0 0.360054"/>
</joint>
<joint name="2_bar_team_1_revolute_joint" type="revolute">
  <parent link="empty_2_bar_team_1"/>
  <child link="2_bar_team_1"/>
  <axis xyz="0 1 0"/>
</joint>

<joint name="5_bar_team_1_prismatic_joint" type="prismatic">
  <parent link="table"/>
  <child link="empty_5_bar_team_1"/>
  <limit effort="9999" velocity="9999" lower="-0.077" upper="0.077"/>
  <axis xyz="0 1 0"/>
  <origin xyz="0.075 0.031126 0.360054"/>
</joint>
<joint name="5_bar_team_1_revolute_joint" type="revolute">
  <parent link="empty_5_bar_team_1"/>
  <child link="5_bar_team_1"/>
  <axis xyz="0 1 0"/>
</joint>

<joint name="3_bar_team_1_prismatic_joint" type="prismatic">
  <parent link="table"/>
  <child link="empty_3_bar_team_1"/>
  <limit effort="9999" velocity="9999" lower="-0.117" upper="0.117"/>
  <axis xyz="0 1 0"/>
  <origin xyz="-0.225 0.0 0.360054"/>
</joint>
<joint name="3_bar_team_1_revolute_joint" type="revolute">
  <parent link="empty_3_bar_team_1"/>
  <child link="3_bar_team_1"/>
  <axis xyz="0 1 0"/>
</joint>






<joint name="goalie_team_2_prismatic_joint" type="prismatic">
  <parent link="table"/>
  <child link="empty_goalie_team_2"/>
  <limit effort="9999" velocity="9999" lower="-0.147" upper="0.147"/>
  <axis xyz="0 1 0"/>
  <origin xyz="-0.525 0.0 0.360054" rpy="0 0 3.1415"/>
</joint>
<joint name="goalie_team_2_revolute_joint" type="revolute">
  <parent link="empty_goalie_team_2"/>
  <child link="goalie_team_2"/>
  <axis xyz="0 1 0"/>
</joint>

<joint name="2_bar_team_2_prismatic_joint" type="prismatic">
  <parent link="table"/>
  <child link="empty_2_bar_team_2"/>
  <limit effort="9999" velocity="9999" lower="-0.187" upper="0.187"/>
  <axis xyz="0 1 0"/>
  <origin xyz="-0.375 0.0 0.360054" rpy="0 0 3.1415"/>
</joint>
<joint name="2_bar_team_2_revolute_joint" type="revolute">
  <parent link="empty_2_bar_team_2"/>
  <child link="2_bar_team_2"/>
  <axis xyz="0 1 0"/>
</joint>

<joint name="5_bar_team_2_prismatic_joint" type="prismatic">
  <parent link="table"/>
  <child link="empty_5_bar_team_2"/>
  <limit effort="9999" velocity="9999" lower="-0.077" upper="0.077"/>
  <axis xyz="0 1 0"/>
  <origin xyz="-0.075 -0.031126 0.360054" rpy="0 0 3.1415"/>
</joint>
<joint name="5_bar_team_2_revolute_joint" type="revolute">
  <parent link="empty_5_bar_team_2"/>
  <child link="5_bar_team_2"/>
  <axis xyz="0 1 0" />
</joint>

<joint name="3_bar_team_2_prismatic_joint" type="prismatic">
  <parent link="table"/>
  <child link="empty_3_bar_team_2"/>
  <limit effort="9999" velocity="9999" lower="-0.117" upper="0.117"/>
  <axis xyz="0 1 0"/>
  <origin xyz="0.225 0.0 0.360054" rpy="0 0 3.1415"/>
</joint>
<joint name="3_bar_team_2_revolute_joint" type="revolute">
  <parent link="empty_3_bar_team_2"/>
  <child link="3_bar_team_2"/>
  <axis xyz="0 1 0"/>
</joint>


</robot>
